[32mINFO    [0m root:conftest.py:25 â€”â€”â€”â€”â€”â€”â€”â€”â€”â€”â€”â€”å¼€å§‹æ‰§è¡Œè‡ªåŠ¨åŒ–æµ‹è¯•â€”â€”â€”â€”â€”â€”â€”â€”â€”â€”â€”â€”â€”â€”â€”â€”â€”â€”
[32mINFO    [0m root:test_HomePage.py:23 
[32mINFO    [0m root:test_HomePage.py:24 ****å¼€å§‹æ‰§è¡Œç”¨ä¾‹****
[33mWARNING [0m urllib3.connectionpool:connectionpool.py:662 Retrying (Retry(total=2, connect=None, read=None, redirect=None, status=None)) after connection broken by 'NewConnectionError('<urllib3.connection.HTTPConnection object at 0x00000000048A7AC8>: Failed to establish a new connection: [Errno 11004] getaddrinfo failed')': /shell
[33mWARNING [0m urllib3.connectionpool:connectionpool.py:662 Retrying (Retry(total=1, connect=None, read=None, redirect=None, status=None)) after connection broken by 'NewConnectionError('<urllib3.connection.HTTPConnection object at 0x00000000048A7DD8>: Failed to establish a new connection: [Errno 11004] getaddrinfo failed')': /shell
[33mWARNING [0m urllib3.connectionpool:connectionpool.py:662 Retrying (Retry(total=0, connect=None, read=None, redirect=None, status=None)) after connection broken by 'NewConnectionError('<urllib3.connection.HTTPConnection object at 0x00000000048A7F98>: Failed to establish a new connection: [Errno 11004] getaddrinfo failed')': /shell